<?xml version="1.0" ?>
<robot name="sphero" xmlns:xacro="http://www.ros.org/wiki/xacro">

  <link name="base_link">
    <inertial>
      <origin rpy="0 0 0" xyz="0.0 0.0 -0.005" />
      <origin rpy="0 0 0" xyz="0.0 0.0 0.0"/>
      <mass value="0.5"/>
      <inertia ixx="1.0" ixy="0.0" ixz="0.0" iyy="1.0" iyz="0.0" izz="1.0"/>
    </inertial>
    <collision>
      <origin rpy="0 0 0" xyz="0 0 0.0"/>
      <geometry>
        <sphere radius="0.01"/>
      </geometry>
    </collision>
    <visual>
      <origin rpy="0 0 0" xyz="0 0 0.0"/>
      <geometry>
        <sphere radius="0.01"/>
      </geometry>
      <material name="orange">
        <color rgba="0 0 .8 1"/>
      </material>
    </visual>
  </link>

  <link name="world"/>
  <joint name="fixed" type="fixed">
    <parent link="world"/>
    <child link="base_link"/>
  </joint>
  
  <link name="base_rotation_link">
    <inertial>
      <origin rpy="0 0 0" xyz="0.0 0.0 0."/>
      <mass value="0.05"/>
      <inertia ixx="0.0029" ixy="0.0" ixz="0.0" iyy="0.0029" iyz="0.0" izz="0.0029"/>
    </inertial>
    <collision>
      <origin rpy="0 0 0" xyz="0 0 0.0"/>
      <geometry>
        <sphere radius="0.01"/>
      </geometry>
    </collision>
    <visual>
      <origin rpy="0 0 0" xyz="0 0 0.0"/>
      <geometry>
        <sphere radius="0.01"/>
      </geometry>
      <material name="blue">
        <color rgba="0 0 .8 1"/>
      </material>
    </visual>
  </link>
  <joint name="rotation_joint" type="revolute">
    <origin rpy="0 0 0" xyz="0.0 0.0 0.0"/>
    <parent link="base_link"/>
    <child link="base_rotation_link"/>
    <axis xyz="0 0 1"/>
    <limit effort="18.85" lower="-1e+16" upper="1e+16" velocity="0.2"/>
  </joint>
  <link name="base_direction_link">
    <inertial>
      <origin rpy="0 0 0" xyz="0.0 0.0 0.0"/>
      <mass value="0.05"/>
      <inertia ixx="0.00029" ixy="0.0" ixz="0.0" iyy="0.00029" iyz="0.0" izz="0.00029"/>
    </inertial>
    <collision>
      <origin rpy="0 0 0" xyz="0 0.0 0.0"/>
      <geometry>
        <sphere radius="0.0381"/>
      </geometry>
    </collision>
    <visual>
      <origin rpy="0 0 0" xyz="0 0.0 0.0"/>
      <geometry>
        <mesh filename="package://sphero_description/meshes/Sphero_Textured.dae" scale="1.3 1.3 1.3"/>
      </geometry>
    </visual>
  </link>
  <joint name="direction_joint" type="continuous">
    <origin rpy="0 0 0" xyz="0.0 0.0 0.0"/>
    <parent link="base_rotation_link"/>
    <child link="base_direction_link"/>
    <axis xyz="1 0 0"/>
    <limit effort="18.85" velocity="0.2"/>
  </joint>
  <gazebo reference="base_link">
    <kp>100000000.0</kp>
    <kd>10.0</kd>
    <mu1>0.1</mu1>
    <mu2>0.1</mu2>
    <fdir1>1 0 0</fdir1>
    <maxVel>10.0</maxVel>
    <minDepth>0.0005</minDepth>
  </gazebo>
  <gazebo reference="base_rotation_link">
    <kp>100000000.0</kp>
    <kd>10.0</kd>
    <mu1>10</mu1>
    <mu2>10</mu2>
    <fdir1>1 0 0</fdir1>
    <maxVel>1.0</maxVel>
    <minDepth>0.0005</minDepth>
  </gazebo>
  <gazebo reference="base_direction_link">
    <kp>100000000.0</kp>
    <kd>10.0</kd>
    <mu1>10</mu1>
    <mu2>10</mu2>
    <fdir1>1 0 0</fdir1>
    <maxVel>1.0</maxVel>
    <minDepth>0.0005</minDepth>
  </gazebo>
  <gazebo reference="rotation_joint">
    <implicitSpringDamper>1</implicitSpringDamper>
  </gazebo>
  <gazebo reference="direction_joint">
    <implicitSpringDamper>1</implicitSpringDamper>
  </gazebo>
  <!-- Differencial drive plugin modified for a sphero robot -->
  <gazebo>
    <plugin filename="libgazebo_sphero_controller.so" name="sphero_gazebo_plugin">
      <alwaysOn>true</alwaysOn>
      <updateRate>30</updateRate>
      <leftJoint>direction_joint</leftJoint>
      <rightJoint>rotation_joint</rightJoint>
      <wheelSeparation>0.0381</wheelSeparation>
      <wheelDiameter>0.01</wheelDiameter>
      <torque>20</torque>
      <commandTopic>/cmd_vel</commandTopic>
      <odometryTopic>/odom</odometryTopic>
      <odometryFrame>/odom_frame</odometryFrame>
      <publishWheelJointState>true</publishWheelJointState>
      <odometrySource>world</odometrySource>
      <robotBaseFrame>base_link</robotBaseFrame>
    </plugin>
  </gazebo>
  <!-- imu -->
  <gazebo>
    <plugin filename="libgazebo_ros_imu.so" name="gazebo_ros_imu_controller">
      <robotNamespace>/sphero/</robotNamespace>
      <topicName>imu/data3</topicName>
      <serviceName>imu/service</serviceName>
      <bodyName>base_link</bodyName>
      <frameId>base_link</frameId>
      <gaussianNoise>0</gaussianNoise>
      <rpyOffsets>0 0 0</rpyOffsets>
      <updateRate>50.0</updateRate>
      <alwaysOn>true</alwaysOn>
      <gaussianNoise>0</gaussianNoise>
    </plugin>
  </gazebo>
  <!-- contact sensor -->
  <!--
  <gazebo>
      <plugin name="gazebo_contact_sensor_plugin" filename="libgazebo_contact_sensor_plugin.so">
      </plugin>
  </gazebo>
  -->
</robot>
